>>> START RUNNING: FedAVG-Equal-Non-IID-01-2.1.1 - Train mode: benchmark - Dataset: chexpert
START LOADING CHEXPERT DATASET...
Init State dim 6
Init Action dim 3
ROUND:  0
[5, 5, 5]
  0%|                                                    | 0/1000 [00:09<?, ?it/s]
multiprocessing.pool.RemoteTraceback:
"""
Traceback (most recent call last):
  File "/home/aiotlab/anaconda3/envs/thanhnt_vaipe/lib/python3.9/multiprocessing/pool.py", line 125, in worker
    result = (True, func(*args, **kwds))
  File "/home/aiotlab/anaconda3/envs/thanhnt_vaipe/lib/python3.9/multiprocessing/pool.py", line 48, in mapstar
    return list(map(*args))
  File "/mnt/disk1/dungnt/federated-learning-dqn/utils/trainer.py", line 40, in train
    _, start_inference_loss = test(model, train_dataloader)
  File "/mnt/disk1/dungnt/federated-learning-dqn/utils/trainer.py", line 90, in test
    output = model(X)
  File "/home/aiotlab/anaconda3/envs/thanhnt_vaipe/lib/python3.9/site-packages/torch/nn/modules/module.py", line 1102, in _call_impl
    return forward_call(*input, **kwargs)
  File "/mnt/disk1/dungnt/federated-learning-dqn/models/resnet18.py", line 122, in forward
    output = self.conv1(x)
  File "/home/aiotlab/anaconda3/envs/thanhnt_vaipe/lib/python3.9/site-packages/torch/nn/modules/module.py", line 1102, in _call_impl
    return forward_call(*input, **kwargs)
  File "/home/aiotlab/anaconda3/envs/thanhnt_vaipe/lib/python3.9/site-packages/torch/nn/modules/container.py", line 141, in forward
    input = module(input)
  File "/home/aiotlab/anaconda3/envs/thanhnt_vaipe/lib/python3.9/site-packages/torch/nn/modules/module.py", line 1102, in _call_impl
    return forward_call(*input, **kwargs)
  File "/home/aiotlab/anaconda3/envs/thanhnt_vaipe/lib/python3.9/site-packages/torch/nn/modules/conv.py", line 446, in forward
    return self._conv_forward(input, self.weight, self.bias)
  File "/home/aiotlab/anaconda3/envs/thanhnt_vaipe/lib/python3.9/site-packages/torch/nn/modules/conv.py", line 442, in _conv_forward
    return F.conv2d(input, weight, bias, self.stride,
RuntimeError: cuDNN error: CUDNN_STATUS_NOT_INITIALIZED
"""
The above exception was the direct cause of the following exception:
Traceback (most recent call last):
  File "/mnt/disk1/dungnt/federated-learning-dqn/train.py", line 344, in <module>
    main(args)
  File "/mnt/disk1/dungnt/federated-learning-dqn/train.py", line 199, in main
    pool.map(
  File "/home/aiotlab/anaconda3/envs/thanhnt_vaipe/lib/python3.9/multiprocessing/pool.py", line 364, in map
    return self._map_async(func, iterable, mapstar, chunksize).get()
  File "/home/aiotlab/anaconda3/envs/thanhnt_vaipe/lib/python3.9/multiprocessing/pool.py", line 771, in get
    raise self._value
RuntimeError: cuDNN error: CUDNN_STATUS_NOT_INITIALIZED