>>> START RUNNING: FedAVG-Equal-Non-IID-01-2.1.1 - Train mode: benchmark - Dataset: chexpert
START LOADING CHEXPERT DATASET...
Init State dim 6
Init Action dim 3
ROUND:  0
[5, 5, 5]
Downloading: "https://github.com/pytorch/vision/archive/v0.10.0.zip" to /home/aiotlab/.cache/torch/hub/v0.10.0.zip
  0%|                                                                                             | 0/1000 [00:10<?, ?it/s]
multiprocessing.pool.RemoteTraceback:
"""
Traceback (most recent call last):
  File "/home/aiotlab/anaconda3/envs/longvaipe/lib/python3.8/multiprocessing/pool.py", line 125, in worker
    result = (True, func(*args, **kwds))
  File "/home/aiotlab/anaconda3/envs/longvaipe/lib/python3.8/multiprocessing/pool.py", line 48, in mapstar
    return list(map(*args))
  File "/mnt/disk1/dungnt/federated-learning-dqn/utils/trainer.py", line 40, in train
    _, start_inference_loss = test(model, train_dataloader)
  File "/mnt/disk1/dungnt/federated-learning-dqn/utils/trainer.py", line 91, in test
    loss += cel(output, y).item()
  File "/home/aiotlab/anaconda3/envs/longvaipe/lib/python3.8/site-packages/torch/nn/modules/module.py", line 1102, in _call_impl
    return forward_call(*input, **kwargs)
  File "/home/aiotlab/anaconda3/envs/longvaipe/lib/python3.8/site-packages/torch/nn/modules/loss.py", line 1150, in forward
    return F.cross_entropy(input, target, weight=self.weight,
  File "/home/aiotlab/anaconda3/envs/longvaipe/lib/python3.8/site-packages/torch/nn/functional.py", line 2846, in cross_entropy
    return torch._C._nn.cross_entropy_loss(input, target, weight, _Reduction.get_enum(reduction), ignore_index, label_smoothing)
RuntimeError: 0D or 1D target tensor expected, multi-target not supported
"""
The above exception was the direct cause of the following exception:
Traceback (most recent call last):
  File "train.py", line 344, in <module>
    main(args)
  File "train.py", line 199, in main
    pool.map(
  File "/home/aiotlab/anaconda3/envs/longvaipe/lib/python3.8/multiprocessing/pool.py", line 364, in map
    return self._map_async(func, iterable, mapstar, chunksize).get()
  File "/home/aiotlab/anaconda3/envs/longvaipe/lib/python3.8/multiprocessing/pool.py", line 771, in get
    raise self._value
RuntimeError: 0D or 1D target tensor expected, multi-target not supported