>>> START RUNNING: FedAVG-Equal-Non-IID-01-2.1.1 - Train mode: benchmark - Dataset: chexpert
START LOADING CHEXPERT DATASET...
Init State dim 6
Init Action dim 3
ROUND:  0
[5, 5, 5]
  0%|                                                 | 0/1000 [00:08<?, ?it/s]
multiprocessing.pool.RemoteTraceback:
"""
Traceback (most recent call last):
  File "/home/aiotlab/anaconda3/envs/longvaipe/lib/python3.8/multiprocessing/pool.py", line 125, in worker
    result = (True, func(*args, **kwds))
  File "/home/aiotlab/anaconda3/envs/longvaipe/lib/python3.8/multiprocessing/pool.py", line 48, in mapstar
    return list(map(*args))
  File "/mnt/disk1/dungnt/federated-learning-dqn/utils/trainer.py", line 40, in train
    _, start_inference_loss = test(model, train_dataloader)
  File "/mnt/disk1/dungnt/federated-learning-dqn/utils/trainer.py", line 87, in test
    for X, y in test_dataloader:
  File "/home/aiotlab/anaconda3/envs/longvaipe/lib/python3.8/site-packages/torch/utils/data/dataloader.py", line 517, in __next__
    data = self._next_data()
  File "/home/aiotlab/anaconda3/envs/longvaipe/lib/python3.8/site-packages/torch/utils/data/dataloader.py", line 557, in _next_data
    data = self._dataset_fetcher.fetch(index)  # may raise StopIteration
  File "/home/aiotlab/anaconda3/envs/longvaipe/lib/python3.8/site-packages/torch/utils/data/_utils/fetch.py", line 44, in fetch
    data = [self.dataset[idx] for idx in possibly_batched_index]
  File "/home/aiotlab/anaconda3/envs/longvaipe/lib/python3.8/site-packages/torch/utils/data/_utils/fetch.py", line 44, in <listcomp>
    data = [self.dataset[idx] for idx in possibly_batched_index]
  File "/mnt/disk1/dungnt/federated-learning-dqn/utils/loader.py", line 216, in __getitem__
    image, label = self.dataset[self.idxs[item]]
  File "/mnt/disk1/dungnt/federated-learning-dqn/utils/loader.py", line 267, in __getitem__
    print(f"label : {label}\nlabel shape: {label.shape}")
AttributeError: 'list' object has no attribute 'shape'
"""
The above exception was the direct cause of the following exception:
Traceback (most recent call last):
  File "train.py", line 344, in <module>
    main(args)
  File "train.py", line 199, in main
    pool.map(
  File "/home/aiotlab/anaconda3/envs/longvaipe/lib/python3.8/multiprocessing/pool.py", line 364, in map
    return self._map_async(func, iterable, mapstar, chunksize).get()
  File "/home/aiotlab/anaconda3/envs/longvaipe/lib/python3.8/multiprocessing/pool.py", line 771, in get
    raise self._value
AttributeError: 'list' object has no attribute 'shape'