2022-01-11 15:53:35,204 INFO    MainThread:5596 [internal.py:wandb_internal():87] W&B internal server running at pid: 5596, started at: 2022-01-11 15:53:35.203912
2022-01-11 15:53:35,209 INFO    WriterThread:5596 [datastore.py:open_for_write():77] open: /Users/thuydungnguyen/workspace/LAB/DQN-FL/LongND-FL-Parallel-Computing/wandb/run-20220111_155332-3e3suso5/run-3e3suso5.wandb
2022-01-11 15:53:35,209 DEBUG   HandlerThread:5596 [handler.py:handle_request():130] handle_request: check_version
2022-01-11 15:53:35,212 DEBUG   SenderThread:5596 [sender.py:send():234] send: header
2022-01-11 15:53:35,212 DEBUG   SenderThread:5596 [sender.py:send_request():248] send_request: check_version
2022-01-11 15:53:35,716 DEBUG   SenderThread:5596 [sender.py:send():234] send: run
2022-01-11 15:53:36,653 WARNING MainThread:5596 [internal.py:wandb_internal():146] Internal process interrupt: 1
2022-01-11 15:54:02,977 WARNING MainThread:5596 [internal.py:wandb_internal():146] Internal process interrupt: 2
2022-01-11 15:54:02,979 ERROR   MainThread:5596 [internal.py:wandb_internal():149] Internal process interrupted.
2022-01-11 15:54:03,807 INFO    WriterThread:5596 [datastore.py:close():281] close: /Users/thuydungnguyen/workspace/LAB/DQN-FL/LongND-FL-Parallel-Computing/wandb/run-20220111_155332-3e3suso5/run-3e3suso5.wandb
2022-01-11 15:54:03,807 INFO    HandlerThread:5596 [handler.py:finish():731] shutting down handler
2022-01-11 15:54:09,286 ERROR   SenderThread:5596 [retry.py:__call__():126] Retry attempt failed:
Traceback (most recent call last):
  File "/Users/thuydungnguyen/opt/anaconda3/envs/sample-federated/lib/python3.9/site-packages/urllib3/connectionpool.py", line 445, in _make_request
    six.raise_from(e, None)
  File "<string>", line 3, in raise_from
  File "/Users/thuydungnguyen/opt/anaconda3/envs/sample-federated/lib/python3.9/site-packages/urllib3/connectionpool.py", line 440, in _make_request
    httplib_response = conn.getresponse()
  File "/Users/thuydungnguyen/opt/anaconda3/envs/sample-federated/lib/python3.9/http/client.py", line 1371, in getresponse
    response.begin()
  File "/Users/thuydungnguyen/opt/anaconda3/envs/sample-federated/lib/python3.9/http/client.py", line 319, in begin
    version, status, reason = self._read_status()
  File "/Users/thuydungnguyen/opt/anaconda3/envs/sample-federated/lib/python3.9/http/client.py", line 280, in _read_status
    line = str(self.fp.readline(_MAXLINE + 1), "iso-8859-1")
  File "/Users/thuydungnguyen/opt/anaconda3/envs/sample-federated/lib/python3.9/socket.py", line 704, in readinto
    return self._sock.recv_into(b)
  File "/Users/thuydungnguyen/opt/anaconda3/envs/sample-federated/lib/python3.9/ssl.py", line 1241, in recv_into
    return self.read(nbytes, buffer)
  File "/Users/thuydungnguyen/opt/anaconda3/envs/sample-federated/lib/python3.9/ssl.py", line 1099, in read
    return self._sslobj.read(len, buffer)
socket.timeout: The read operation timed out

During handling of the above exception, another exception occurred:

Traceback (most recent call last):
  File "/Users/thuydungnguyen/opt/anaconda3/envs/sample-federated/lib/python3.9/site-packages/requests/adapters.py", line 439, in send
    resp = conn.urlopen(
  File "/Users/thuydungnguyen/opt/anaconda3/envs/sample-federated/lib/python3.9/site-packages/urllib3/connectionpool.py", line 755, in urlopen
    retries = retries.increment(
  File "/Users/thuydungnguyen/opt/anaconda3/envs/sample-federated/lib/python3.9/site-packages/urllib3/util/retry.py", line 532, in increment
    raise six.reraise(type(error), error, _stacktrace)
  File "/Users/thuydungnguyen/opt/anaconda3/envs/sample-federated/lib/python3.9/site-packages/urllib3/packages/six.py", line 770, in reraise
    raise value
  File "/Users/thuydungnguyen/opt/anaconda3/envs/sample-federated/lib/python3.9/site-packages/urllib3/connectionpool.py", line 699, in urlopen
    httplib_response = self._make_request(
  File "/Users/thuydungnguyen/opt/anaconda3/envs/sample-federated/lib/python3.9/site-packages/urllib3/connectionpool.py", line 447, in _make_request
    self._raise_timeout(err=e, url=url, timeout_value=read_timeout)
  File "/Users/thuydungnguyen/opt/anaconda3/envs/sample-federated/lib/python3.9/site-packages/urllib3/connectionpool.py", line 336, in _raise_timeout
    raise ReadTimeoutError(
urllib3.exceptions.ReadTimeoutError: HTTPSConnectionPool(host='api.wandb.ai', port=443): Read timed out. (read timeout=10)

During handling of the above exception, another exception occurred:

Traceback (most recent call last):
  File "/Users/thuydungnguyen/opt/anaconda3/envs/sample-federated/lib/python3.9/site-packages/wandb/sdk/lib/retry.py", line 102, in __call__
    result = self._call_fn(*args, **kwargs)
  File "/Users/thuydungnguyen/opt/anaconda3/envs/sample-federated/lib/python3.9/site-packages/wandb/sdk/internal/internal_api.py", line 141, in execute
    return self.client.execute(*args, **kwargs)
  File "/Users/thuydungnguyen/opt/anaconda3/envs/sample-federated/lib/python3.9/site-packages/wandb/vendor/gql-0.2.0/gql/client.py", line 52, in execute
    result = self._get_result(document, *args, **kwargs)
  File "/Users/thuydungnguyen/opt/anaconda3/envs/sample-federated/lib/python3.9/site-packages/wandb/vendor/gql-0.2.0/gql/client.py", line 60, in _get_result
    return self.transport.execute(document, *args, **kwargs)
  File "/Users/thuydungnguyen/opt/anaconda3/envs/sample-federated/lib/python3.9/site-packages/wandb/vendor/gql-0.2.0/gql/transport/requests.py", line 38, in execute
    request = requests.post(self.url, **post_args)
  File "/Users/thuydungnguyen/opt/anaconda3/envs/sample-federated/lib/python3.9/site-packages/requests/api.py", line 117, in post
    return request('post', url, data=data, json=json, **kwargs)
  File "/Users/thuydungnguyen/opt/anaconda3/envs/sample-federated/lib/python3.9/site-packages/requests/api.py", line 61, in request
    return session.request(method=method, url=url, **kwargs)
  File "/Users/thuydungnguyen/opt/anaconda3/envs/sample-federated/lib/python3.9/site-packages/requests/sessions.py", line 542, in request
    resp = self.send(prep, **send_kwargs)
  File "/Users/thuydungnguyen/opt/anaconda3/envs/sample-federated/lib/python3.9/site-packages/requests/sessions.py", line 655, in send
    r = adapter.send(request, **kwargs)
  File "/Users/thuydungnguyen/opt/anaconda3/envs/sample-federated/lib/python3.9/site-packages/requests/adapters.py", line 529, in send
    raise ReadTimeout(e, request=request)
requests.exceptions.ReadTimeout: HTTPSConnectionPool(host='api.wandb.ai', port=443): Read timed out. (read timeout=10)
2022-01-11 15:54:37,681 INFO    SenderThread:5596 [dir_watcher.py:__init__():169] watching files in: /Users/thuydungnguyen/workspace/LAB/DQN-FL/LongND-FL-Parallel-Computing/wandb/run-20220111_155332-3e3suso5/files
2022-01-11 15:54:37,682 INFO    SenderThread:5596 [sender.py:_start_run_threads():804] run started: 3e3suso5 with start time 1641891212
2022-01-11 15:54:37,683 INFO    SenderThread:5596 [sender.py:finish():1070] shutting down sender
2022-01-11 15:54:37,683 INFO    SenderThread:5596 [dir_watcher.py:finish():283] shutting down directory watcher
2022-01-11 15:54:38,684 INFO    SenderThread:5596 [dir_watcher.py:finish():313] scan: /Users/thuydungnguyen/workspace/LAB/DQN-FL/LongND-FL-Parallel-Computing/wandb/run-20220111_155332-3e3suso5/files
2022-01-11 15:54:38,684 INFO    SenderThread:5596 [dir_watcher.py:finish():327] scan save: /Users/thuydungnguyen/workspace/LAB/DQN-FL/LongND-FL-Parallel-Computing/wandb/run-20220111_155332-3e3suso5/files/config.yaml config.yaml
2022-01-11 15:54:38,684 INFO    SenderThread:5596 [file_pusher.py:finish():177] shutting down file pusher
2022-01-11 15:54:38,684 INFO    SenderThread:5596 [file_pusher.py:join():182] waiting for file pusher
2022-01-11 15:54:54,264 INFO    Thread-10 :5596 [upload_job.py:push():137] Uploaded file /Users/thuydungnguyen/workspace/LAB/DQN-FL/LongND-FL-Parallel-Computing/wandb/run-20220111_155332-3e3suso5/files/config.yaml
2022-01-11 15:55:01,331 INFO    MainThread:5596 [internal.py:handle_exit():77] Internal process exited
